Workbook
Name in_capex: 'Inputs & Assumptions'!$B$18
Name in_discount_rate: 'Inputs & Assumptions'!$B$20
Name in_energy_price: 'Inputs & Assumptions'!$B$9
Name in_fcr: 'Inputs & Assumptions'!$B$8
Name in_feed_price: 'Inputs & Assumptions'!$B$7
Name in_flow_m3h: 'Inputs & Assumptions'!$B$13
Name in_hours: 'Inputs & Assumptions'!$B$12
Name in_hurdle_rate: 'Inputs & Assumptions'!$B$21
Name in_labour: 'Inputs & Assumptions'!$B$15
Name in_load_factor: 'Inputs & Assumptions'!$B$11
Name in_load_kw: 'Inputs & Assumptions'!$B$10
Name in_maint_pct: 'Inputs & Assumptions'!$B$16
Name in_other_opex: 'Inputs & Assumptions'!$B$17
Name in_out_qty: 'Inputs & Assumptions'!$B$5
Name in_project_life: 'Inputs & Assumptions'!$B$22
Name in_sale_price: 'Inputs & Assumptions'!$B$6
Name in_scale_exp: 'Inputs & Assumptions'!$B$19
Name in_water_util: 'Inputs & Assumptions'!$B$14
Name INP_ABB_CIRCUIT_BREAKER: 'Inputs Master (M0)'!$C$36
Name INP_ABB_CIRCUIT_BREAKERS: 'Inputs Master (M0)'!$C$33
Name INP_ACTUATED_VALVES: 'Inputs Master (M0)'!$C$14
Name INP_BATCH_SIZE: 'Inputs Master (M0)'!$C$7
Name INP_CONSUMABLE_INTENSITY_RATIO: 'Inputs Master (M0)'!$C$17
Name INP_CONSUMABLES_PRICE_DOSING_CHEMICALS_NUTRIENT_FERTILISER_STOCK_FILTER_MEDIA_MEMBRANES: 'Inputs Master (M0)'!$C$16
Name INP_CORPUS_MEDIAN_CLEANING_TANK_1_4_M_DIA_X_1_3_M: 'Inputs Master (M0)'!$C$50
Name INP_CORPUS_MEDIAN_GAC_FILTER_1_3_M_DIA_X_1_4_M: 'Inputs Master (M0)'!$C$47
Name INP_CORPUS_MEDIAN_HOOGENDOORN_ISII_REMOTE_MONITORING: 'Inputs Master (M0)'!$C$48
Name INP_CORPUS_MEDIAN_LEVEL_TRANSMITTER_0_1_4_M: 'Inputs Master (M0)'!$C$49
Name INP_CORPUS_MEDIAN_SOFTENER_VESSEL_1_2_M_DIA_X_1_3_M: 'Inputs Master (M0)'!$C$46
Name INP_CORPUS_MEDIAN_UV_DISINFECTION_4_KW_600X510X660_MM: 'Inputs Master (M0)'!$C$45
Name INP_CULTIVATION_CONTAINERS: 'Inputs Master (M0)'!$C$10
Name INP_DESIGN_LIFE: 'Inputs Master (M0)'!$C$8
Name INP_DISCOUNT_RATE: 'Inputs Master (M0)'!$C$26
Name INP_ELECTRICAL_LOAD_FACTOR: 'Inputs Master (M0)'!$C$19
Name INP_ENERGY_PRICE: 'Inputs Master (M0)'!$C$18
Name INP_EPC_ENGINEERING_FACTOR: 'Inputs Master (M0)'!$C$43
Name INP_FOAK_CONTINGENCY_FACTOR: 'Inputs Master (M0)'!$C$42
Name INP_GRUNDFOS_FERTIGATION_DOSING_PUMP: 'Inputs Master (M0)'!$C$40
Name INP_INSTALL_FACTOR: 'Inputs Master (M0)'!$C$41
Name INP_INSTALLED_COST_FACTOR_CENTRAL: 'Inputs Master (M0)'!$C$44
Name INP_INVESTOR_HURDLE_RATE_IRR: 'Inputs Master (M0)'!$C$27
Name INP_IRRIGATION_DEMAND_M3_PER_HR: 'Inputs Master (M0)'!$C$9
Name INP_LABOUR: 'Inputs Master (M0)'!$C$22
Name INP_MAINTENANCE: 'Inputs Master (M0)'!$C$23
Name INP_OPERATING_HOURS: 'Inputs Master (M0)'!$C$20
Name INP_OTHER_OPEX: 'Inputs Master (M0)'!$C$24
Name INP_PENTAIR_STRUCTURAL_SOFTENER_VESSEL: 'Inputs Master (M0)'!$C$39
Name INP_PRAHER_BACKWASH_SERVICE_VALVE_NEST: 'Inputs Master (M0)'!$C$37
Name INP_PROCESS_FLUID_DENSITY_ENGINE_DEFAULT: 'Inputs Master (M0)'!$C$29
Name INP_PROJECT_LIFE: 'Inputs Master (M0)'!$C$28
Name INP_RO_PERMEATE_CAPACITY_M3_PER_HR: 'Inputs Master (M0)'!$C$11
Name INP_RO_RECOVERY_PERCENT: 'Inputs Master (M0)'!$C$12
Name INP_SALE_PRICE_PER_OUTPUT_UNIT: 'Inputs Master (M0)'!$C$15
Name INP_SCALING_EXPONENT_N_CAPEX_OUTPUT_N: 'Inputs Master (M0)'!$C$25
Name INP_STANDARD_GRAVITATIONAL_ACCELERATION: 'Inputs Master (M0)'!$C$32
Name INP_SWEET_SPOT_CAPACITY_SCALING_EXPONENT_N: 'Inputs Master (M0)'!$C$30
Name INP_TDK_LAMBDA_3_PHASE_POWER_INPUT: 'Inputs Master (M0)'!$C$35
Name INP_UNIT_COST_CEILING: 'Inputs Master (M0)'!$C$6
Name INP_WAGO_TERMINAL_BLOCKS: 'Inputs Master (M0)'!$C$34
Name INP_WATER_DENSITY_PUMP_SIZING_WORKED_CALC: 'Inputs Master (M0)'!$C$31

Sheet Executive Summary
A1: ForgeOS Engineering Dossier — Water treatment
A2: ="⬤ TAB QUALITY "&IF(ISNUMBER('Quality & Audit'!$B$31),IF('Quality & Audit'!$B$31=INT('Quality & Audit'!$B$31),TEXT('Quality & Audit'!$B$31,"0"),TEXT('Quality & Audit'!$B$31,"0.0")),"—")&"/10 · "&IF(ISNUMBER('Quality & Audit'!$B$31),IF('Quality & Audit'!$B$31>=8,"PASS","FAIL"),"UNSCORED")&" (target ≥8, live from the Quality & Audit score cell)"&" · MIRROR of the dossier floor (min of every deterministic section & non-mirror tab) — re-stamped from the CURRENT scores, never a stale earlier cap; own content check: cov…"&" · full audit: Quality & Audit tab" -> ⬤ TAB QUALITY 9/10 · PASS (target ≥8, live from the Quality & Audit score cell) · MIRROR of the dossier floor (min of every deterministic section & non-mirror tab) — re-stamped from the CURRENT scores, never a stale earlier cap; own content check: cov… · full audit: Quality & Audit tab
A3: The engineering reality of your hardware idea — a buildable design, a real bill of materials, the true cost, and who can make it. The detail is in the tabs; this page is the summary.
A5: WHAT IT IS
A6: Water treatment
A8: OUTPUT
A9: 45 m3/h
A10: Irrigation Demand M3 Per
A12: ALL-IN INSTALLED COST
A13: £1,360,613
A15: STATUS
A16: =IF('Quality & Audit'!$B$66=0,"SHIPS","DRAFT — "&'Quality & Audit'!$B$66&" open issue"&IF('Quality & Audit'!$B$66=1,"","s")) -> SHIPS
A17: One verdict for the whole dossier — the floor is the minimum score of every section and tab; it ships when all are ≥8. Detail: Quality & Audit tab.
J21: SG: The original Codema quote was for 2 x 90m3 and 1 x 45m3 system with RO etc for 1.1m Euros.
A22: This dossier specifies a Water treatment — 45 m3/h (irrigation demand m3 per). The engine values the build at £1,360,613 (all-in installed cost). An independent market benchmark flags 1 dimension where the design diverges from the brief/market expectation — see the ⚠ Checks tab for the routed detail. Every figure in this workbook — the bill of materials, the costs, and the specifications below — is derived deterministically from the engineering contract, computed rather than estimated by hand. | J22: SG: Does the model take into account inflation each year and material price index rises etc?
A26: Key specifications & brief compliance — every target deterministically verified
A27: Brief metric | B27: Target | C27: Unit | D27: Matched contract quantity | E27: Achieved | F27: Direction | G27: STATUS | H27: Note | I27: Cell check
A28: Irrigation demand (m³/h) | B28: 45 | C28: m3/h | D28: Irrigation pump flow (m³/h) | E28: 90 | F28: ≥ target (meet/exceed) | G28: =IF(E28>=B28-0.9,"PASS","FAIL") -> PASS | H28: brief key: irrigation_demand_m3_per_hr → contract: irrigation_pump_flow_m3_h · unit family: flow_m3h | I28: =IF(AND(LEN(TRIM(A28&""))>0,TRIM(A28&"")<>"—",LEN(TRIM(B28&""))>0,TRIM(B28&"")<>"—",LEN(TRIM(G28&""))>0,TRIM(G28&"")<>"—"),"PASS","⚠ FAIL — "&"a required cell is empty/placeholder or wrong type") -> PASS | J28: SG: Why is it providing double capacity required? May be a good thing for resilience of the system etc maybe.
A29: Cultivation containers | B29: 6000 | C29: count | D29: Cultivation container count | E29: 6000 | F29: ≥ target (meet/exceed) | G29: =IF(E29>=B29-120,"PASS","FAIL") -> PASS | H29: brief key: cultivation_containers → contract: cultivation_container_count · unit family: count | I29: =IF(AND(LEN(TRIM(A29&""))>0,TRIM(A29&"")<>"—",LEN(TRIM(B29&""))>0,TRIM(B29&"")<>"—",LEN(TRIM(G29&""))>0,TRIM(G29&"")<>"—"),"PASS","⚠ FAIL — "&"a required cell is empty/placeholder or wrong type") -> PASS | J29: SG: 45m3/hr for 6,000 containers sounds low. Is a 'container' more like a bench tray? Maybe language issue.
A30: Ro permeate capacity (m³/h) | B30: 8 | C30: m3/h | D30: Ro permeate capacity (m³/h) | E30: 8 | F30: ≥ target (meet/exceed) | G30: =IF(E30>=B30-0.16,"PASS","FAIL") -> PASS | H30: brief key: ro_permeate_capacity_m3_per_hr → contract: ro_permeate_capacity_m3_h · unit family: flow_m3h | I30: =IF(AND(LEN(TRIM(A30&""))>0,TRIM(A30&"")<>"—",LEN(TRIM(B30&""))>0,TRIM(B30&"")<>"—",LEN(TRIM(G30&""))>0,TRIM(G30&"")<>"—"),"PASS","⚠ FAIL — "&"a required cell is empty/placeholder or wrong type") -> PASS | J30: SG: RO capacity for 6,000 containers again sounds low.
A31: Ro recovery (%) | B31: 75 | C31: % | D31: Ro recovery (%) | E31: 75 | F31: ≥ target (meet/exceed) | G31: =IF(E31>=B31-1.5,"PASS","FAIL") -> PASS | H31: brief key: ro_recovery_percent → contract: ro_recovery_percent | I31: =IF(AND(LEN(TRIM(A31&""))>0,TRIM(A31&"")<>"—",LEN(TRIM(B31&""))>0,TRIM(B31&"")<>"—",LEN(TRIM(G31&""))>0,TRIM(G31&"")<>"—"),"PASS","⚠ FAIL — "&"a required cell is empty/placeholder or wrong type") -> PASS
A32: Water storage capacity m3 | B32: 120 | C32: m3 | D32: Water storage capacity m3 | E32: 120 | F32: ≥ target (meet/exceed) | G32: =IF(E32>=B32-2.4,"PASS","FAIL") -> PASS | H32: brief key: water_storage_capacity_m3 → contract: water_storage_capacity_m3 · unit family: volume_m3 | I32: =IF(AND(LEN(TRIM(A32&""))>0,TRIM(A32&"")<>"—",LEN(TRIM(B32&""))>0,TRIM(B32&"")<>"—",LEN(TRIM(G32&""))>0,TRIM(G32&"")<>"—"),"PASS","⚠ FAIL — "&"a required cell is empty/placeholder or wrong type") -> PASS
A33: Actuated valves | B33: 200 | C33: count | D33: Actuated distribution valve count | E33: 200 | F33: ≥ target (meet/exceed) | G33: =IF(E33>=B33-4,"PASS","FAIL") -> PASS | H33: brief key: actuated_valves → contract: actuated_distribution_valve_count · unit family: count | I33: =IF(AND(LEN(TRIM(A33&""))>0,TRIM(A33&"")<>"—",LEN(TRIM(B33&""))>0,TRIM(B33&"")<>"—",LEN(TRIM(G33&""))>0,TRIM(G33&"")<>"—"),"PASS","⚠ FAIL — "&"a required cell is empty/placeholder or wrong type") -> PASS
A35: Where the money goes — capex by category
A36: Pipework & valves | B36: 339593 | D36: 41.6 | E36: █████████████████
A37: Filtration & membranes | B37: 111964 | D37: 13.7 | E37: █████
A38: Controls & instrumentation | B38: 110691 | D38: 13.6 | E38: █████
A39: Vessels, tanks & columns | B39: 108361 | D39: 13.3 | E39: █████
A40: Other equipment | B40: 65562 | D40: 8 | E40: ███
A41: Rotating equipment | B41: 35261 | D41: 4.3 | E41: ██
A42: Power & electrical | B42: 34221 | D42: 4.2 | E42: ██
A44: What's inside this workbook
A45: • Bill of Materials (Ledger) | B45: The bill — tag, item, qty, unit £, cost basis, spec.
A46: • Cost waterfall | B46: Bill of materials to installed price, with live running totals.
A47: • Financial model | B47: Economics, scenarios and investment analysis, live off the Inputs tab.
A48: • Calculations | B48: Worked calculations by tool — live Excel formulas where structured.
A49: • Risk & Regulatory | B49: Hazard and risk register, compliance verdict and statutory duties.
A50: • Connection trace | B50: Which part connects to what, with live cell references.
A52: Your next steps — from design to a funded factory
A53: • You have the engineering dossier
...

Sheet Contents
A1: Contents
A2: ="⬤ TAB QUALITY "&IF(ISNUMBER('Quality & Audit'!$B$63),IF('Quality & Audit'!$B$63=INT('Quality & Audit'!$B$63),TEXT('Quality & Audit'!$B$63,"0"),TEXT('Quality & Audit'!$B$63,"0.0")),"—")&"/10 · "&IF(ISNUMBER('Quality & Audit'!$B$63),IF('Quality & Audit'!$B$63>=8,"PASS","FAIL"),"UNSCORED")&" (target ≥8, live from the Quality & Audit score cell)"&" · index integrity (both directions) — index rows point at an existing tab 32/32; every sheet listed in the index 32/32; cell completeness+type contract 96/96 · score = min…"&" · full audit: Quality & Audit tab" -> ⬤ TAB QUALITY 10/10 · PASS (target ≥8, live from the Quality & Audit score cell) · index integrity (both directions) — index rows point at an existing tab 32/32; every sheet listed in the index 32/32; cell completeness+type contract 96/96 · score = min… · full audit: Quality & Audit tab
A3: Click any tab name to jump to it. Each data tab has a '↑ Contents' link at its top-right to come back. Yellow cells anywhere are editable inputs; green cells are live formulas.
A4: # | B4: Tab | C4: What's on it | D4: Cell check
A5: 1 | B5: Executive Summary | C5: The cover — what it is, cost, verdict and next steps. | D5: =IF(AND(LEN(TRIM(A5&""))>0,TRIM(A5&"")<>"—",LEN(TRIM(B5&""))>0,TRIM(B5&"")<>"—",LEN(TRIM(C5&""))>0,TRIM(C5&"")<>"—"),"PASS","⚠ FAIL — "&"a required cell is empty/placeholder or wrong type") -> PASS
A6: 2 | B6: Inputs Master (M0) | C6: Every primitive number behind the model, with class and provenance. | D6: =IF(AND(LEN(TRIM(A6&""))>0,TRIM(A6&"")<>"—",LEN(TRIM(B6&""))>0,TRIM(B6&"")<>"—",LEN(TRIM(C6&""))>0,TRIM(C6&"")<>"—"),"PASS","⚠ FAIL — "&"a required cell is empty/placeholder or wrong type") -> PASS
A7: 3 | B7: Equipment & Dimensions Register | C7: Every manifest part — geometry, volume formula, MPN, coverage. | D7: =IF(AND(LEN(TRIM(A7&""))>0,TRIM(A7&"")<>"—",LEN(TRIM(B7&""))>0,TRIM(B7&"")<>"—",LEN(TRIM(C7&""))>0,TRIM(C7&"")<>"—"),"PASS","⚠ FAIL — "&"a required cell is empty/placeholder or wrong type") -> PASS
A8: 4 | B8: Overview | C8: Run provenance, quality scorecard and headline metrics. | D8: =IF(AND(LEN(TRIM(A8&""))>0,TRIM(A8&"")<>"—",LEN(TRIM(B8&""))>0,TRIM(B8&"")<>"—",LEN(TRIM(C8&""))>0,TRIM(C8&"")<>"—"),"PASS","⚠ FAIL — "&"a required cell is empty/placeholder or wrong type") -> PASS
A9: 5 | B9: Renders | C9: Photoreal render gallery — interior hero, plan and exterior views. | D9: =IF(AND(LEN(TRIM(A9&""))>0,TRIM(A9&"")<>"—",LEN(TRIM(B9&""))>0,TRIM(B9&"")<>"—",LEN(TRIM(C9&""))>0,TRIM(C9&"")<>"—"),"PASS","⚠ FAIL — "&"a required cell is empty/placeholder or wrong type") -> PASS
A10: 6 | B10: Cost waterfall | C10: Bill of materials to installed price, with live running totals. | D10: =IF(AND(LEN(TRIM(A10&""))>0,TRIM(A10&"")<>"—",LEN(TRIM(B10&""))>0,TRIM(B10&"")<>"—",LEN(TRIM(C10&""))>0,TRIM(C10&"")<>"—"),"PASS","⚠ FAIL — "&"a required cell is empty/placeholder or wrong type") -> PASS
A11: 7 | B11: Financial model | C11: Economics, scenarios and investment analysis, live off the Inputs tab. | D11: =IF(AND(LEN(TRIM(A11&""))>0,TRIM(A11&"")<>"—",LEN(TRIM(B11&""))>0,TRIM(B11&"")<>"—",LEN(TRIM(C11&""))>0,TRIM(C11&"")<>"—"),"PASS","⚠ FAIL — "&"a required cell is empty/placeholder or wrong type") -> PASS
A12: 8 | B12: Bill of Materials (Ledger) | C12: The bill — tag, item, qty, unit £, cost basis, spec. | D12: =IF(AND(LEN(TRIM(A12&""))>0,TRIM(A12&"")<>"—",LEN(TRIM(B12&""))>0,TRIM(B12&"")<>"—",LEN(TRIM(C12&""))>0,TRIM(C12&"")<>"—"),"PASS","⚠ FAIL — "&"a required cell is empty/placeholder or wrong type") -> PASS
A13: 9 | B13: Brief | C13: Original client brief and the engine's structured interpretation. | D13: =IF(AND(LEN(TRIM(A13&""))>0,TRIM(A13&"")<>"—",LEN(TRIM(B13&""))>0,TRIM(B13&"")<>"—",LEN(TRIM(C13&""))>0,TRIM(C13&"")<>"—"),"PASS","⚠ FAIL — "&"a required cell is empty/placeholder or wrong type") -> PASS
A14: 10 | B14: Design basis | C14: Codes, design duties, fluid and utilisation basis — with sources. | D14: =IF(AND(LEN(TRIM(A14&""))>0,TRIM(A14&"")<>"—",LEN(TRIM(B14&""))>0,TRIM(B14&"")<>"—",LEN(TRIM(C14&""))>0,TRIM(C14&"")<>"—"),"PASS","⚠ FAIL — "&"a required cell is empty/placeholder or wrong type") -> PASS
A15: 11 | B15: Drawings | C15: Drawing register — number, revision, scale, sheets and full-size A1 files. | D15: =IF(AND(LEN(TRIM(A15&""))>0,TRIM(A15&"")<>"—",LEN(TRIM(B15&""))>0,TRIM(B15&"")<>"—",LEN(TRIM(C15&""))>0,TRIM(C15&"")<>"—"),"PASS","⚠ FAIL — "&"a required cell is empty/placeholder or wrong type") -> PASS
A16: 12 | B16: BFD — Block Flow | C16: Block flow diagram — major process blocks & streams. | D16: =IF(AND(LEN(TRIM(A16&""))>0,TRIM(A16&"")<>"—",LEN(TRIM(B16&""))>0,TRIM(B16&"")<>"—",LEN(TRIM(C16&""))>0,TRIM(C16&"")<>"—"),"PASS","⚠ FAIL — "&"a required cell is empty/placeholder or wrong type") -> PASS
... A36: 32 | B36: Audit data | C36: Embedded operands every live verdict formula references, with provenance. | D36: =IF(AND(LEN(TRIM(A36&""))>0,TRIM(A36&"")<>"—",LEN(TRIM(B36&""))>0,TRIM(B36&"")<>"—",LEN(TRIM(C36&""))>0,TRIM(C36&"")<>"—"),"PASS","⚠ FAIL — "&"a required cell is empty/placeholder or wrong type") -> PASS

Sheet Inputs Master (M0)
A1: M0 — Inputs Master: every primitive number the model is built from | H1: ↑ Contents
A2: ="⬤ TAB QUALITY "&IF(ISNUMBER('Quality & Audit'!$B$60),IF('Quality & Audit'!$B$60=INT('Quality & Audit'!$B$60),TEXT('Quality & Audit'!$B$60,"0"),TEXT('Quality & Audit'!$B$60,"0.0")),"—")&"/10 · "&IF(ISNUMBER('Quality & Audit'!$B$60),IF('Quality & Audit'!$B$60>=8,"PASS","FAIL"),"UNSCORED")&" (target ≥8, live from the Quality & Audit score cell)"&" · cell completeness+type contract 270/270 · score = min over checks of 10 × passed/checked"&" · full audit: Quality & Audit tab" -> ⬤ TAB QUALITY 10/10 · PASS (target ≥8, live from the Quality & Audit score cell) · cell completeness+type contract 270/270 · score = min over checks of 10 × passed/checked · full audit: Quality & Audit tab
A3: A PRIMITIVE = a number with NO in-model ancestor: brief-stated, a class assumption (open until the customer confirms), a physics constant, a live catalogue/distributor price, or a margin/install/corpus factor. Every row mints an Excel DEFINED NAME (Ref) so a downstream formula can reference it by name and self-document. Phase A: this register exists, fully cited. Phase B rewires the rest of the workbook to reference these cells live.
A5: Ref | B5: Label | C5: Value | D5: Units | E5: Class | F5: Provenance | G5: Used-by count | H5: Cell check
A6: INP_UNIT_COST_CEILING | B6: Unit cost ceiling | C6: 1400000 | D6: GBP | E6: brief | F6: brief: "…per year - Unit cost ceiling: approximately £1,250,000 to £1,400,000 installed for the water, storage, fertigation, irrigation a…" | G6: 0 | H6: =IF(AND(LEN(TRIM(A6&""))>0,TRIM(A6&"")<>"—",LEN(TRIM(B6&""))>0,TRIM(B6&"")<>"—",LEN(TRIM(C6&""))>0,TRIM(C6&"")<>"—",ISNUMBER(C6),LEN(TRIM(D6&""))>0,TRIM(D6&"")<>"—",LEN(TRIM(E6&""))>0,TRIM(E6&"")<>"—",LEN(TRIM(F6&""))>0,TRIM(F6&"")<>"—"),"PASS","⚠ FAIL — "&"a required cell is empty/placeholder or wrong type") -> PASS | J6: SG: What defines this ceiling?
A7: INP_BATCH_SIZE | B7: Batch size | C7: 6 | D7: count | E7: brief | F7: brief: "…al turnkey supplier offer (Codema Systems Group, offer 3201262, "Farm 2", 2020) totalling €1,395,019. Target market: ind…" | G7: 113 | H7: =IF(AND(LEN(TRIM(A7&""))>0,TRIM(A7&"")<>"—",LEN(TRIM(B7&""))>0,TRIM(B7&"")<>"—",LEN(TRIM(C7&""))>0,TRIM(C7&"")<>"—",ISNUMBER(C7),LEN(TRIM(D7&""))>0,TRIM(D7&"")<>"—",LEN(TRIM(E7&""))>0,TRIM(E7&"")<>"—",LEN(TRIM(F7&""))>0,TRIM(F7&"")<>"—"),"PASS","⚠ FAIL — "&"a required cell is empty/placeholder or wrong type") -> PASS
A8: INP_DESIGN_LIFE | B8: Design life | C8: 20 | D8: years | E8: brief | F8: brief: "…a real turnkey supplier offer (Codema Systems Group, offer 3201262, "Farm 2", 2020) totalling €1,395,019. Target market:…" | G8: 108 | H8: =IF(AND(LEN(TRIM(A8&""))>0,TRIM(A8&"")<>"—",LEN(TRIM(B8&""))>0,TRIM(B8&"")<>"—",LEN(TRIM(C8&""))>0,TRIM(C8&"")<>"—",ISNUMBER(C8),LEN(TRIM(D8&""))>0,TRIM(D8&"")<>"—",LEN(TRIM(E8&""))>0,TRIM(E8&"")<>"—",LEN(TRIM(F8&""))>0,TRIM(F8&"")<>"—"),"PASS","⚠ FAIL — "&"a required cell is empty/placeholder or wrong type") -> PASS
A9: INP_IRRIGATION_DEMAND_M3_PER_HR | B9: Irrigation demand m3 per hr | C9: 45 | D9: m3/h | E9: brief | F9: brief: "…R (FERTIGATION) UNITS — two A/B nutrient-dosing units, each 45 cubic metres per hour, for the multi-layer ebb/flow system,…" | G9: 43 | H9: =IF(AND(LEN(TRIM(A9&""))>0,TRIM(A9&"")<>"—",LEN(TRIM(B9&""))>0,TRIM(B9&"")<>"—",LEN(TRIM(C9&""))>0,TRIM(C9&"")<>"—",ISNUMBER(C9),LEN(TRIM(D9&""))>0,TRIM(D9&"")<>"—",LEN(TRIM(E9&""))>0,TRIM(E9&"")<>"—",LEN(TRIM(F9&""))>0,TRIM(F9&"")<>"—"),"PASS","⚠ FAIL — "&"a required cell is empty/placeholder or wrong type") -> PASS
A10: INP_CULTIVATION_CONTAINERS | B10: Cultivation containers | C10: 6000 | D10: count | E10: brief | F10: brief: "…ayers per tunnel, 4 rows per layer, 15 containers per row — 6,000 cultivation containers total, each 2,760 by 1,290 millimetr…" | G10: 10 | H10: =IF(AND(LEN(TRIM(A10&""))>0,TRIM(A10&"")<>"—",LEN(TRIM(B10&""))>0,TRIM(B10&"")<>"—",LEN(TRIM(C10&""))>0,TRIM(C10&"")<>"—",ISNUMBER(C10),LEN(TRIM(D10&""))>0,TRIM(D10&"")<>"—",LEN(TRIM(E10&""))>0,TRIM(E10&"")<>"—",LEN(TRIM(F10&""))>0,TRIM(F10&"")<>"—"),"PASS","⚠ FAIL — "&"a required cell is empty/placeholder or wrong type") -> PASS
A11: INP_RO_PERMEATE_CAPACITY_M3_PER_HR | B11: Ro permeate capacity m3 per hr | C11: 8 | D11: m3/h | E11: brief | F11: brief: "…tem needs. - Reverse-osmosis unit: hourly permeate capacity 8.0 cubic metres per hour, raw-tap-water blending capacity 1.2…" | G11: 58 | H11: =IF(AND(LEN(TRIM(A11&""))>0,TRIM(A11&"")<>"—",LEN(TRIM(B11&""))>0,TRIM(B11&"")<>"—",LEN(TRIM(C11&""))>0,TRIM(C11&"")<>"—",ISNUMBER(C11),LEN(TRIM(D11&""))>0,TRIM(D11&"")<>"—",LEN(TRIM(E11&""))>0,TRIM(E11&"")<>"—",LEN(TRIM(F11&""))>0,TRIM(F11&"")<>"—"),"PASS","⚠ FAIL — "&"a required cell is empty/placeholder or wrong type") -> PASS
A12: INP_RO_RECOVERY_PERCENT | B12: Ro recovery percent | C12: 75 | D12: % | E12: brief | F12: brief: "…capacity 1.2 to 1.6 cubic metres per hour, recovery factor 75 percent, working pressure 10.6 bar at 15 degrees Celsius fe…" | G12: 7 | H12: =IF(AND(LEN(TRIM(A12&""))>0,TRIM(A12&"")<>"—",LEN(TRIM(B12&""))>0,TRIM(B12&"")<>"—",LEN(TRIM(C12&""))>0,TRIM(C12&"")<>"—",ISNUMBER(C12),LEN(TRIM(D12&""))>0,TRIM(D12&"")<>"—",LEN(TRIM(E12&""))>0,TRIM(E12&"")<>"—",LEN(TRIM(F12&""))>0,TRIM(F12&"")<>"—"),"PASS","⚠ FAIL — "&"a required cell is empty/placeholder or wrong type") -> PASS
A13: INP_WATER_STORAGE_CAPACITY_M3 | B13: Water storage capacity m3 | C13: 120 | D13: m3 | E13: brief | F13: brief.constraints.target_performance.metrics[water_storage_capacity_m3] (source: user) | G13: 4 | H13: =IF(AND(LEN(TRIM(A13&""))>0,TRIM(A13&"")<>"—",LEN(TRIM(B13&""))>0,TRIM(B13&"")<>"—",LEN(TRIM(C13&""))>0,TRIM(C13&"")<>"—",ISNUMBER(C13),LEN(TRIM(D13&""))>0,TRIM(D13&"")<>"—",LEN(TRIM(E13&""))>0,TRIM(E13&"")<>"—",LEN(TRIM(F13&""))>0,TRIM(F13&"")<>"—"),"PASS","⚠ FAIL — "&"a required cell is empty/placeholder or wrong type") -> PASS
A14: INP_ACTUATED_VALVES | B14: Actuated valves | C14: 200 | D14: count | E14: brief | F14: brief: "…iner at 1.5 cubic metres per hour; 30 containers per valve, 200 electrically-actuated valves; one valve per department open…" | G14: 14 | H14: =IF(AND(LEN(TRIM(A14&""))>0,TRIM(A14&"")<>"—",LEN(TRIM(B14&""))>0,TRIM(B14&"")<>"—",LEN(TRIM(C14&""))>0,TRIM(C14&"")<>"—",ISNUMBER(C14),LEN(TRIM(D14&""))>0,TRIM(D14&"")<>"—",LEN(TRIM(E14&""))>0,TRIM(E14&"")<>"—",LEN(TRIM(F14&""))>0,TRIM(F14&"")<>"—"),"PASS","⚠ FAIL — "&"a required cell is empty/placeholder or wrong type") -> PASS
A15: INP_SALE_PRICE_PER_OUTPUT_UNIT | B15: Sale price (per output unit) | C15: 0 | D15: £/m3/h | E15: assumption | F15: UNVERIFIED — no per-unit market price is derivable for this class. Enter a real sale price to make the economics tabs meaningful; until then revenue / EBITDA / IRR are not valid. — ASSUMPTION, open until the customer confirms (see 'Questions for the customer') | G15: 147 | H15: =IF(AND(LEN(TRIM(A15&""))>0,TRIM(A15&"")<>"—",LEN(TRIM(B15&""))>0,TRIM(B15&"")<>"—",LEN(TRIM(C15&""))>0,TRIM(C15&"")<>"—",ISNUMBER(C15),LEN(TRIM(D15&""))>0,TRIM(D15&"")<>"—",LEN(TRIM(E15&""))>0,TRIM(E15&"")<>"—",LEN(TRIM(F15&""))>0,TRIM(F15&"")<>"—"),"PASS","⚠ FAIL — "&"a required cell is empty/placeholder or wrong type") -> PASS
A16: INP_CONSUMABLES_PRICE_DOSING_CHEMICALS_NUTRIENT_FERTILISER_STOCK_FILTER_MEDIA_MEMBRANES | B16: Consumables price (dosing chemicals · nutrient / fertiliser stock · filter media & membranes) | C16: 0 | D16: £/m3/h | E16: assumption | F16: consumable classes derived from the plant's own process/media BoM + contract lines — what it ACTUALLY consumes (not a 'feedstock'); enter a real £ per output unit to price them (0 until priced — meanwhile carried inside 'Other opex') — ASSUMPTION, open until the customer confirms (see 'Questions for the customer') | G16: 147 | H16: =IF(AND(LEN(TRIM(A16&""))>0,TRIM(A16&"")<>"—",LEN(TRIM(B16&""))>0,TRIM(B16&"")<>"—",LEN(TRIM(C16&""))>0,TRIM(C16&"")<>"—",ISNUMBER(C16),LEN(TRIM(D16&""))>0,TRIM(D16&"")<>"—",LEN(TRIM(E16&""))>0,TRIM(E16&"")<>"—",LEN(TRIM(F16&""))>0,TRIM(F16&"")<>"—"),"PASS","⚠ FAIL — "&"a required cell is empty/placeholder or wrong type") -> PASS
A17: INP_CONSUMABLE_INTENSITY_RATIO | B17: Consumable intensity ratio | C17: 0 | D17: ratio | E17: assumption | F17: consumable units per output unit (multiplies the consumables price above); 0 until priced — ASSUMPTION, open until the customer confirms (see 'Questions for the customer') | G17: 147 | H17: =IF(AND(LEN(TRIM(A17&""))>0,TRIM(A17&"")<>"—",LEN(TRIM(B17&""))>0,TRIM(B17&"")<>"—",LEN(TRIM(C17&""))>0,TRIM(C17&"")<>"—",ISNUMBER(C17),LEN(TRIM(D17&""))>0,TRIM(D17&"")<>"—",LEN(TRIM(E17&""))>0,TRIM(E17&"")<>"—",LEN(TRIM(F17&""))>0,TRIM(F17&"")<>"—"),"PASS","⚠ FAIL — "&"a required cell is empty/placeholder or wrong type") -> PASS
A18: INP_ENERGY_PRICE | B18: Energy price | C18: 0.15 | D18: £/kWh | E18: assumption | F18: assumed — UK industrial electricity ~£0.15/kWh (edit to your tariff) — ASSUMPTION, open until the customer confirms (see 'Questions for the customer') | G18: 0 | H18: =IF(AND(LEN(TRIM(A18&""))>0,TRIM(A18&"")<>"—",LEN(TRIM(B18&""))>0,TRIM(B18&"")<>"—",LEN(TRIM(C18&""))>0,TRIM(C18&"")<>"—",ISNUMBER(C18),LEN(TRIM(D18&""))>0,TRIM(D18&"")<>"—",LEN(TRIM(E18&""))>0,TRIM(E18&"")<>"—",LEN(TRIM(F18&""))>0,TRIM(F18&"")<>"—"),"PASS","⚠ FAIL — "&"a required cell is empty/placeholder or wrong type") -> PASS
... A50: INP_CORPUS_MEDIAN_CLEANING_TANK_1_4_M_DIA_X_1_3_M | B50: Corpus median — Cleaning Tank · 1.4 m dia x 1.3 m | C50: 8082 | D50: £ | E50: factor | F50: corpus anchor, median £8,082, n=5 · tag TK-102 | G50: 2 | H50: =IF(AND(LEN(TRIM(A50&""))>0,TRIM(A50&"")<>"—",LEN(TRIM(B50&""))>0,TRIM(B50&"")<>"—",LEN(TRIM(C50&""))>0,TRIM(C50&"")<>"—",ISNUMBER(C50),LEN(TRIM(D50&""))>0,TRIM(D50&"")<>"—",LEN(TRIM(E50&""))>0,TRIM(E50&"")<>"—",LEN(TRIM(F50&""))>0,TRIM(F50&"")<>"—"),"PASS","⚠ FAIL — "&"a required cell is empty/placeholder or wrong type") -> PASS

Sheet Equipment & Dimensions Register
A1: Equipment & Dimensions Register — one row per manifest part, self-auditing geometry | P1: ↑ Contents
A2: ="⬤ TAB QUALITY "&IF(ISNUMBER('Quality & Audit'!$B$61),IF('Quality & Audit'!$B$61=INT('Quality & Audit'!$B$61),TEXT('Quality & Audit'!$B$61,"0"),TEXT('Quality & Audit'!$B$61,"0.0")),"—")&"/10 · "&IF(ISNUMBER('Quality & Audit'!$B$61),IF('Quality & Audit'!$B$61>=8,"PASS","FAIL"),"UNSCORED")&" (target ≥8, live from the Quality & Audit score cell)"&" · cell completeness+type contract 417/423 · score = min over checks of 10 × passed/checked"&" · full audit: Quality & Audit tab" -> ⬤ TAB QUALITY 9.9/10 · PASS (target ≥8, live from the Quality & Audit score cell) · cell completeness+type contract 417/423 · score = min over checks of 10 × passed/checked · full audit: Quality & Audit tab
A3: VOLUME and FOOTPRINT are IN-CELL FORMULAS over the L/W/H or D/H columns — corrupt a dimension and they move on recalc, never a python-baked number. 'Canonical name' is the ONE name registry for this part; the two check columns cross-reference the BoM ledger and the drawing-name match this SAME part got from parts_ledger.py's covered() — where the surfaces genuinely diverge, the check FAILS honestly rather than being forced green.
A5: Tag | B5: Canonical name | C5: Module | D5: Shape | E5: L (mm) | F5: W (mm) | G5: H (mm) | H5: D (mm) | I5: Volume (m3) | J5: Footprint (m2) | K5: Material | L5: MPN / status | M5: Drawing appearances | N5: Name in BoM (live check) | O5: Name in drawings (live check) | P5: Cell check
A6: D-101 | B6: 3 Phase Power Input | C6: Power distribution | D6: box | E6: 1600 | F6: 860 | G6: 2100 | I6: =IF(H6<>"",PI()*(H6/2000)^2*(G6/1000),IF(AND(E6<>"",F6<>"",G6<>""),E6/1000*F6/1000*G6/1000,"")) -> 2.8896 | J6: =IF(H6<>"",PI()*(H6/2000)^2,IF(AND(E6<>"",F6<>""),E6/1000*F6/1000,"")) -> 1.376 | K6: n/a — not a fabricated part (bought-out assembly) | L6: TDK-Lambda DRB240-24-3-A0 · IDENTIFIED | M6: 5/7 | N6: =IF(COUNTIF('Bill of Materials (Ledger)'!$B$5:$B$415,"*"&B6&"*")>0,"PASS","FAIL — "&"canonical name not found in the BoM ledger Item column") -> PASS | O6: =IF('Audit data'!$D$10>0,"PASS","FAIL — "&"canonical name not matched in any drawing surface (5/7 surfaces)") -> PASS | P6: =IF(AND(LEN(TRIM(A6&""))>0,TRIM(A6&"")<>"—",LEN(TRIM(B6&""))>0,TRIM(B6&"")<>"—",LEN(TRIM(C6&""))>0,TRIM(C6&"")<>"—",LEN(TRIM(D6&""))>0,TRIM(D6&"")<>"—",LEN(TRIM(K6&""))>0,TRIM(K6&"")<>"—",LEN(TRIM(L6&""))>0,TRIM(L6&"")<>"—",LEN(TRIM(M6&""))>0,TRIM(M6&"")<>"—",LEN(TRIM(N6&""))>0,TRIM(N6&"")<>"—",LEN(TRIM(O6&""))>0,TRIM(O6&"")<>"—"),"PASS","⚠ FAIL — "&"a required cell is empty/placeholder or wrong type") -> PASS
A7: EP-101 | B7: Main Switchboard | C7: Energy storage source | D7: box | E7: 1600 | F7: 860 | G7: 2100 | I7: =IF(H7<>"",PI()*(H7/2000)^2*(G7/1000),IF(AND(E7<>"",F7<>"",G7<>""),E7/1000*F7/1000*G7/1000,"")) -> 2.8896 | J7: =IF(H7<>"",PI()*(H7/2000)^2,IF(AND(E7<>"",F7<>""),E7/1000*F7/1000,"")) -> 1.376 | K7: n/a — not a fabricated part (bought-out assembly) | L7: Schneider Electric BlokSeT MB301M · IDENTIFIED | M7: 5/7 | N7: =IF(COUNTIF('Bill of Materials (Ledger)'!$B$5:$B$415,"*"&B7&"*")>0,"PASS","FAIL — "&"canonical name not found in the BoM ledger Item column") -> PASS | O7: =IF('Audit data'!$D$11>0,"PASS","FAIL — "&"canonical name not matched in any drawing surface (5/7 surfaces)") -> PASS | P7: =IF(AND(LEN(TRIM(A7&""))>0,TRIM(A7&"")<>"—",LEN(TRIM(B7&""))>0,TRIM(B7&"")<>"—",LEN(TRIM(C7&""))>0,TRIM(C7&"")<>"—",LEN(TRIM(D7&""))>0,TRIM(D7&"")<>"—",LEN(TRIM(K7&""))>0,TRIM(K7&"")<>"—",LEN(TRIM(L7&""))>0,TRIM(L7&"")<>"—",LEN(TRIM(M7&""))>0,TRIM(M7&"")<>"—",LEN(TRIM(N7&""))>0,TRIM(N7&"")<>"—",LEN(TRIM(O7&""))>0,TRIM(O7&"")<>"—"),"PASS","⚠ FAIL — "&"a required cell is empty/placeholder or wrong type") -> PASS
A8: EP-102 | B8: Mains Incomer | C8: Energy storage source | D8: box | E8: 1600 | F8: 860 | G8: 2100 | I8: =IF(H8<>"",PI()*(H8/2000)^2*(G8/1000),IF(AND(E8<>"",F8<>"",G8<>""),E8/1000*F8/1000*G8/1000,"")) -> 2.8896 | J8: =IF(H8<>"",PI()*(H8/2000)^2,IF(AND(E8<>"",F8<>""),E8/1000*F8/1000,"")) -> 1.376 | K8: n/a — not a fabricated part (bought-out assembly) | L8: ABB 1SDA067417R1 · IDENTIFIED | M8: 3/7 | N8: =IF(COUNTIF('Bill of Materials (Ledger)'!$B$5:$B$415,"*"&B8&"*")>0,"PASS","FAIL — "&"canonical name not found in the BoM ledger Item column") -> PASS | O8: =IF('Audit data'!$D$12>0,"PASS","FAIL — "&"canonical name not matched in any drawing surface (3/7 surfaces)") -> PASS | P8: =IF(AND(LEN(TRIM(A8&""))>0,TRIM(A8&"")<>"—",LEN(TRIM(B8&""))>0,TRIM(B8&"")<>"—",LEN(TRIM(C8&""))>0,TRIM(C8&"")<>"—",LEN(TRIM(D8&""))>0,TRIM(D8&"")<>"—",LEN(TRIM(K8&""))>0,TRIM(K8&"")<>"—",LEN(TRIM(L8&""))>0,TRIM(L8&"")<>"—",LEN(TRIM(M8&""))>0,TRIM(M8&"")<>"—",LEN(TRIM(N8&""))>0,TRIM(N8&"")<>"—",LEN(TRIM(O8&""))>0,TRIM(O8&"")<>"—"),"PASS","⚠ FAIL — "&"a required cell is empty/placeholder or wrong type") -> PASS
A9: EP-103 | B9: SCADA / Plant Control System | C9: Power distribution | D9: box | E9: 700 | F9: 820 | G9: 1800 | I9: =IF(H9<>"",PI()*(H9/2000)^2*(G9/1000),IF(AND(E9<>"",F9<>"",G9<>""),E9/1000*F9/1000*G9/1000,"")) -> 1.0332 | J9: =IF(H9<>"",PI()*(H9/2000)^2,IF(AND(E9<>"",F9<>""),E9/1000*F9/1000,"")) -> 0.574 | K9: n/a — not a fabricated part (bought-out assembly) | L9: process-support system (catalogue class) · SYSTEM | M9: 7/7 | N9: =IF(COUNTIF('Bill of Materials (Ledger)'!$B$5:$B$415,"*"&B9&"*")>0,"PASS","FAIL — "&"canonical name not found in the BoM ledger Item column") -> PASS | O9: =IF('Audit data'!$D$13>0,"PASS","FAIL — "&"canonical name not matched in any drawing surface (7/7 surfaces)") -> PASS | P9: =IF(AND(LEN(TRIM(A9&""))>0,TRIM(A9&"")<>"—",LEN(TRIM(B9&""))>0,TRIM(B9&"")<>"—",LEN(TRIM(C9&""))>0,TRIM(C9&"")<>"—",LEN(TRIM(D9&""))>0,TRIM(D9&"")<>"—",LEN(TRIM(K9&""))>0,TRIM(K9&"")<>"—",LEN(TRIM(L9&""))>0,TRIM(L9&"")<>"—",LEN(TRIM(M9&""))>0,TRIM(M9&"")<>"—",LEN(TRIM(N9&""))>0,TRIM(N9&"")<>"—",LEN(TRIM(O9&""))>0,TRIM(O9&"")<>"—"),"PASS","⚠ FAIL — "&"a required cell is empty/placeholder or wrong type") -> PASS
A10: EP-104 | B10: Motor Control Center | C10: Power distribution | D10: box | E10: 1600 | F10: 1020 | G10: 2100 | I10: =IF(H10<>"",PI()*(H10/2000)^2*(G10/1000),IF(AND(E10<>"",F10<>"",G10<>""),E10/1000*F10/1000*G10/1000,"")) -> 3.4272 | J10: =IF(H10<>"",PI()*(H10/2000)^2,IF(AND(E10<>"",F10<>""),E10/1000*F10/1000,"")) -> 1.632 | K10: n/a — not a fabricated part (bought-out assembly) | L10: Eaton Freedom 2100 · IDENTIFIED | M10: 4/7 | N10: =IF(COUNTIF('Bill of Materials (Ledger)'!$B$5:$B$415,"*"&B10&"*")>0,"PASS","FAIL — "&"canonical name not found in the BoM ledger Item column") -> PASS | O10: =IF('Audit data'!$D$14>0,"PASS","FAIL — "&"canonical name not matched in any drawing surface (4/7 surfaces)") -> PASS | P10: =IF(AND(LEN(TRIM(A10&""))>0,TRIM(A10&"")<>"—",LEN(TRIM(B10&""))>0,TRIM(B10&"")<>"—",LEN(TRIM(C10&""))>0,TRIM(C10&"")<>"—",LEN(TRIM(D10&""))>0,TRIM(D10&"")<>"—",LEN(TRIM(K10&""))>0,TRIM(K10&"")<>"—",LEN(TRIM(L10&""))>0,TRIM(L10&"")<>"—",LEN(TRIM(M10&""))>0,TRIM(M10&"")<>"—",LEN(TRIM(N10&""))>0,TRIM(N10&"")<>"—",LEN(TRIM(O10&""))>0,TRIM(O10&"")<>"—"),"PASS","⚠ FAIL — "&"a required cell is empty/placeholder or wrong type") -> PASS
A11: G-201 | B11: Standby Diesel Generator | C11: Power distribution | D11: box | E11: 862 | F11: 733 | G11: 948 | I11: =IF(H11<>"",PI()*(H11/2000)^2*(G11/1000),IF(AND(E11<>"",F11<>"",G11<>""),E11/1000*F11/1000*G11/1000,"")) -> 0.59899001 | J11: =IF(H11<>"",PI()*(H11/2000)^2,IF(AND(E11<>"",F11<>""),E11/1000*F11/1000,"")) -> 0.631846 | K11: n/a — not a fabricated part (bought-out assembly) | L11: balance-of-plant system (catalogue class) · UTILITY | M11: 4/7 | N11: =IF(COUNTIF('Bill of Materials (Ledger)'!$B$5:$B$415,"*"&B11&"*")>0,"PASS","FAIL — "&"canonical name not found in the BoM ledger Item column") -> PASS | O11: =IF('Audit data'!$D$15>0,"PASS","FAIL — "&"canonical name not matched in any drawing surface (4/7 surfaces)") -> PASS | P11: =IF(AND(LEN(TRIM(A11&""))>0,TRIM(A11&"")<>"—",LEN(TRIM(B11&""))>0,TRIM(B11&"")<>"—",LEN(TRIM(C11&""))>0,TRIM(C11&"")<>"—",LEN(TRIM(D11&""))>0,TRIM(D11&"")<>"—",LEN(TRIM(K11&""))>0,TRIM(K11&"")<>"—",LEN(TRIM(L11&""))>0,TRIM(L11&"")<>"—",LEN(TRIM(M11&""))>0,TRIM(M11&"")<>"—",LEN(TRIM(N11&""))>0,TRIM(N11&"")<>"—",LEN(TRIM(O11&""))>0,TRIM(O11&"")<>"—"),"PASS","⚠ FAIL — "&"a required cell is empty/placeholder or wrong type") -> PASS
A12: I-102 | B12: Electrical Control Cabinet | C12: Safety protection | D12: box | E12: 372.5 | F12: 570 | G12: 600 | I12: =IF(H12<>"",PI()*(H12/2000)^2*(G12/1000),IF(AND(E12<>"",F12<>"",G12<>""),E12/1000*F12/1000*G12/1000,"")) -> 0.127395 | J12: =IF(H12<>"",PI()*(H12/2000)^2,IF(AND(E12<>"",F12<>""),E12/1000*F12/1000,"")) -> 0.212325 | K12: structural steel | L12: made to spec (structural) · BESPOKE | M12: 5/7 | N12: =IF(COUNTIF('Bill of Materials (Ledger)'!$B$5:$B$415,"*"&B12&"*")>0,"PASS","FAIL — "&"canonical name not found in the BoM ledger Item column") -> PASS | O12: =IF('Audit data'!$D$16>0,"PASS","FAIL — "&"canonical name not matched in any drawing surface (5/7 surfaces)") -> PASS | P12: =IF(AND(LEN(TRIM(A12&""))>0,TRIM(A12&"")<>"—",LEN(TRIM(B12&""))>0,TRIM(B12&"")<>"—",LEN(TRIM(C12&""))>0,TRIM(C12&"")<>"—",LEN(TRIM(D12&""))>0,TRIM(D12&"")<>"—",LEN(TRIM(K12&""))>0,TRIM(K12&"")<>"—",LEN(TRIM(L12&""))>0,TRIM(L12&"")<>"—",LEN(TRIM(M12&""))>0,TRIM(M12&"")<>"—",LEN(TRIM(N12&""))>0,TRIM(N12&"")<>"—",LEN(TRIM(O12&""))>0,TRIM(O12&"")<>"—"),"PASS","⚠ FAIL — "&"a required cell is empty/placeholder or wrong type") -> PASS
A13: I-103 | B13: Digital Control Panel | C13: Control compute communication | D13: box | E13: 372.5 | F13: 570 | G13: 410 | I13: =IF(H13<>"",PI()*(H13/2000)^2*(G13/1000),IF(AND(E13<>"",F13<>"",G13<>""),E13/1000*F13/1000*G13/1000,"")) -> 0.08705325 | J13: =IF(H13<>"",PI()*(H13/2000)^2,IF(AND(E13<>"",F13<>""),E13/1000*F13/1000,"")) -> 0.212325 | K13: n/a — not a fabricated part (bought-out assembly) | L13: Siemens 6AV2123-2GB03-0AX0 · IDENTIFIED | M13: 5/7 | N13: =IF(COUNTIF('Bill of Materials (Ledger)'!$B$5:$B$415,"*"&B13&"*")>0,"PASS","FAIL — "&"canonical name not found in the BoM ledger Item column") -> PASS | O13: =IF('Audit data'!$D$17>0,"PASS","FAIL — "&"canonical name not matched in any drawing surface (5/7 surfaces)") -> PASS | P13: =IF(AND(LEN(TRIM(A13&""))>0,TRIM(A13&"")<>"—",LEN(TRIM(B13&""))>0,TRIM(B13&"")<>"—",LEN(TRIM(C13&""))>0,TRIM(C13&"")<>"—",LEN(TRIM(D13&""))>0,TRIM(D13&"")<>"—",LEN(TRIM(K13&""))>0,TRIM(K13&"")<>"—",LEN(TRIM(L13&""))>0,TRIM(L13&"")<>"—",LEN(TRIM(M13&""))>0,TRIM(M13&"")<>"—",LEN(TRIM(N13&""))>0,TRIM(N13&"")<>"—",LEN(TRIM(O13&""))>0,TRIM(O13&"")<>"—"),"PASS","⚠ FAIL — "&"a required cell is empty/placeholder or wrong type") -> PASS
A14: M-101 | B14: Distribution Manifold | C14: Mass fluid transport process | D14: cylinder | G14: 1930 | H14: 372 | I14: =IF(H14<>"",PI()*(H14/2000)^2*(G14/1000),IF(AND(E14<>"",F14<>"",G14<>""),E14/1000*F14/1000*G14/1000,"")) -> 0.20976502 | J14: =IF(H14<>"",PI()*(H14/2000)^2,IF(AND(E14<>"",F14<>""),E14/1000*F14/1000,"")) -> 0.10868654 | K14: PVC-U / 304 stainless (WRAS) | L14: requirement stated — parametric · NOT FOUND | M14: 5/7 | N14: =IF(COUNTIF('Bill of Materials (Ledger)'!$B$5:$B$415,"*"&B14&"*")>0,"PASS","FAIL — "&"canonical name not found in the BoM ledger Item column") -> PASS | O14: =IF('Audit data'!$D$18>0,"PASS","FAIL — "&"canonical name not matched in any drawing surface (5/7 surfaces)") -> PASS | P14: =IF(AND(LEN(TRIM(A14&""))>0,TRIM(A14&"")<>"—",LEN(TRIM(B14&""))>0,TRIM(B14&"")<>"—",LEN(TRIM(C14&""))>0,TRIM(C14&"")<>"—",LEN(TRIM(D14&""))>0,TRIM(D14&"")<>"—",LEN(TRIM(K14&""))>0,TRIM(K14&"")<>"—",LEN(TRIM(L14&""))>0,TRIM(L14&"")<>"—",LEN(TRIM(M14&""))>0,TRIM(M14&"")<>"—",LEN(TRIM(N14&""))>0,TRIM(N14&"")<>"—",LEN(TRIM(O14&""))>0,TRIM(O14&"")<>"—"),"PASS","⚠ FAIL — "&"a required cell is empty/placeholder or wrong type") -> PASS
A15: P-101 | B15: Ro High Pressure Pump | C15: Mass fluid transport process | D15: box | E15: 600 | F15: 510 | G15: 660 | I15: =IF(H15<>"",PI()*(H15/2000)^2*(G15/1000),IF(AND(E15<>"",F15<>"",G15<>""),E15/1000*F15/1000*G15/1000,"")) -> 0.20196 | J15: =IF(H15<>"",PI()*(H15/2000)^2,IF(AND(E15<>"",F15<>""),E15/1000*F15/1000,"")) -> 0.306 | K15: PVC-U / 304 stainless (WRAS) | L15: Grundfos 96502039 · IDENTIFIED | M15: 7/7 | N15: =IF(COUNTIF('Bill of Materials (Ledger)'!$B$5:$B$415,"*"&B15&"*")>0,"PASS","FAIL — "&"canonical name not found in the BoM ledger Item column") -> PASS | O15: =IF('Audit data'!$D$19>0,"PASS","FAIL — "&"canonical name not matched in any drawing surface (7/7 surfaces)") -> PASS | P15: =IF(AND(LEN(TRIM(A15&""))>0,TRIM(A15&"")<>"—",LEN(TRIM(B15&""))>0,TRIM(B15&"")<>"—",LEN(TRIM(C15&""))>0,TRIM(C15&"")<>"—",LEN(TRIM(D15&""))>0,TRIM(D15&"")<>"—",LEN(TRIM(K15&""))>0,TRIM(K15&"")<>"—",LEN(TRIM(L15&""))>0,TRIM(L15&"")<>"—",LEN(TRIM(M15&""))>0,TRIM(M15&"")<>"—",LEN(TRIM(N15&""))>0,TRIM(N15&"")<>"—",LEN(TRIM(O15&""))>0,TRIM(O15&"")<>"—"),"PASS","⚠ FAIL — "&"a required cell is empty/placeholder or wrong type") -> PASS
A16: P-102 | B16: Hand Watering Pump | C16: Mass fluid transport process | D16: box | E16: 900 | F16: 500 | G16: 700 | I16: =IF(H16<>"",PI()*(H16/2000)^2*(G16/1000),IF(AND(E16<>"",F16<>"",G16<>""),E16/1000*F16/1000*G16/1000,"")) -> 0.315 | J16: =IF(H16<>"",PI()*(H16/2000)^2,IF(AND(E16<>"",F16<>""),E16/1000*F16/1000,"")) -> 0.45 | K16: PVC-U / 304 stainless (WRAS) | L16: Grundfos 96935501 · IDENTIFIED | M16: 7/7 | N16: =IF(COUNTIF('Bill of Materials (Ledger)'!$B$5:$B$415,"*"&B16&"*")>0,"PASS","FAIL — "&"canonical name not found in the BoM ledger Item column") -> PASS | O16: =IF('Audit data'!$D$20>0,"PASS","FAIL — "&"canonical name not matched in any drawing surface (7/7 surfaces)") -> PASS | P16: =IF(AND(LEN(TRIM(A16&""))>0,TRIM(A16&"")<>"—",LEN(TRIM(B16&""))>0,TRIM(B16&"")<>"—",LEN(TRIM(C16&""))>0,TRIM(C16&"")<>"—",LEN(TRIM(D16&""))>0,TRIM(D16&"")<>"—",LEN(TRIM(K16&""))>0,TRIM(K16&"")<>"—",LEN(TRIM(L16&""))>0,TRIM(L16&"")<>"—",LEN(TRIM(M16&""))>0,TRIM(M16&"")<>"—",LEN(TRIM(N16&""))>0,TRIM(N16&"")<>"—",LEN(TRIM(O16&""))>0,TRIM(O16&"")<>"—"),"PASS","⚠ FAIL — "&"a required cell is empty/placeholder or wrong type") -> PASS
A17: P-103 | B17: Drain Transfer Pump | C17: Mass fluid transport process | D17: box | E17: 600 | F17: 510 | G17: 660 | I17: =IF(H17<>"",PI()*(H17/2000)^2*(G17/1000),IF(AND(E17<>"",F17<>"",G17<>""),E17/1000*F17/1000*G17/1000,"")) -> 0.20196 | J17: =IF(H17<>"",PI()*(H17/2000)^2,IF(AND(E17<>"",F17<>""),E17/1000*F17/1000,"")) -> 0.306 | K17: PVC-U / 304 stainless (WRAS) | L17: Grundfos 96539165 · IDENTIFIED | M17: 6/7 | N17: =IF(COUNTIF('Bill of Materials (Ledger)'!$B$5:$B$415,"*"&B17&"*")>0,"PASS","FAIL — "&"canonical name not found in the BoM ledger Item column") -> PASS | O17: =IF('Audit data'!$D$21>0,"PASS","FAIL — "&"canonical name not matched in any drawing surface (6/7 surfaces)") -> PASS | P17: =IF(AND(LEN(TRIM(A17&""))>0,TRIM(A17&"")<>"—",LEN(TRIM(B17&""))>0,TRIM(B17&"")<>"—",LEN(TRIM(C17&""))>0,TRIM(C17&"")<>"—",LEN(TRIM(D17&""))>0,TRIM(D17&"")<>"—",LEN(TRIM(K17&""))>0,TRIM(K17&"")<>"—",LEN(TRIM(L17&""))>0,TRIM(L17&"")<>"—",LEN(TRIM(M17&""))>0,TRIM(M17&"")<>"—",LEN(TRIM(N17&""))>0,TRIM(N17&"")<>"—",LEN(TRIM(O17&""))>0,TRIM(O17&"")<>"—"),"PASS","⚠ FAIL — "&"a required cell is empty/placeholder or wrong type") -> PASS
A18: P-104 | B18: Drain Transfer Pump | C18: Mass fluid transport process | D18: box | E18: 600 | F18: 510 | G18: 660 | I18: =IF(H18<>"",PI()*(H18/2000)^2*(G18/1000),IF(AND(E18<>"",F18<>"",G18<>""),E18/1000*F18/1000*G18/1000,"")) -> 0.20196 | J18: =IF(H18<>"",PI()*(H18/2000)^2,IF(AND(E18<>"",F18<>""),E18/1000*F18/1000,"")) -> 0.306 | K18: PVC-U / 304 stainless (WRAS) | L18: Grundfos SL1.50.65.22.2.50D.C · IDENTIFIED | M18: 7/7 | N18: =IF(COUNTIF('Bill of Materials (Ledger)'!$B$5:$B$415,"*"&B18&"*")>0,"PASS","FAIL — "&"canonical name not found in the BoM ledger Item column") -> PASS | O18: =IF('Audit data'!$D$22>0,"PASS","FAIL — "&"canonical name not matched in any drawing surface (7/7 surfaces)") -> PASS | P18: =IF(AND(LEN(TRIM(A18&""))>0,TRIM(A18&"")<>"—",LEN(TRIM(B18&""))>0,TRIM(B18&"")<>"—",LEN(TRIM(C18&""))>0,TRIM(C18&"")<>"—",LEN(TRIM(D18&""))>0,TRIM(D18&"")<>"—",LEN(TRIM(K18&""))>0,TRIM(K18&"")<>"—",LEN(TRIM(L18&""))>0,TRIM(L18&"")<>"—",LEN(TRIM(M18&""))>0,TRIM(M18&"")<>"—",LEN(TRIM(N18&""))>0,TRIM(N18&"")<>"—",LEN(TRIM(O18&""))>0,TRIM(O18&"")<>"—"),"PASS","⚠ FAIL — "&"a required cell is empty/placeholder or wrong type") -> PASS
A19: P-105 | B19: Irrigation Pump | C19: Mass fluid transport process | D19: box | E19: 1379 | F19: 766 | G19: 1073 | I19: =IF(H19<>"",PI()*(H19/2000)^2*(G19/1000),IF(AND(E19<>"",F19<>"",G19<>""),E19/1000*F19/1000*G19/1000,"")) -> 1.1334249 | J19: =IF(H19<>"",PI()*(H19/2000)^2,IF(AND(E19<>"",F19<>""),E19/1000*F19/1000,"")) -> 1.056314 | K19: — | L19: — · — | M19: — | N19: =IF(COUNTIF('Bill of Materials (Ledger)'!$B$5:$B$415,"*"&B19&"*")>0,"PASS","FAIL — "&"canonical name not found in the BoM ledger Item column") -> PASS | O19: =IF('Audit data'!$D$23>0,"PASS","FAIL — "&"canonical name not matched in any drawing surface (0/0 surfaces)") -> FAIL — canonical name not matched in any drawing surface (0/0 surfaces) | P19: =IF(AND(LEN(TRIM(A19&""))>0,TRIM(A19&"")<>"—",LEN(TRIM(B19&""))>0,TRIM(B19&"")<>"—",LEN(TRIM(C19&""))>0,TRIM(C19&"")<>"—",LEN(TRIM(D19&""))>0,TRIM(D19&"")<>"—",LEN(TRIM(K19&""))>0,TRIM(K19&"")<>"—",TRIM(K19&"")<>"—",LEN(TRIM(L19&""))>0,TRIM(L19&"")<>"—",LEN(TRIM(M19&""))>0,TRIM(M19&"")<>"—",TRIM(M19&"")<>"—",LEN(TRIM(N19&""))>0,TRIM(N19&"")<>"—",LEN(TRIM(O19&""))>0,TRIM(O19&"")<>"—"),"PASS","⚠ FAIL — "&"'Material' placeholder '—'; 'Drawing appearances' placeholder '—'") -> ⚠ FAIL — 'Material' placeholder '—'; 'Drawing appearances' placeholder '—'
A20: P-106 | B20: Fertigation Dosing Pump | C20: Mass fluid transport process | D20: box | E20: 600 | F20: 510 | G20: 660 | I20: =IF(H20<>"",PI()*(H20/2000)^2*(G20/1000),IF(AND(E20<>"",F20<>"",G20<>""),E20/1000*F20/1000*G20/1000,"")) -> 0.20196 | J20: =IF(H20<>"",PI()*(H20/2000)^2,IF(AND(E20<>"",F20<>""),E20/1000*F20/1000,"")) -> 0.306 | K20: PVC-U / 304 stainless (WRAS) | L20: Grundfos 96122012 · IDENTIFIED | M20: 7/7 | N20: =IF(COUNTIF('Bill of Materials (Ledger)'!$B$5:$B$415,"*"&B20&"*")>0,"PASS","FAIL — "&"canonical name not found in the BoM ledger Item column") -> PASS | O20: =IF('Audit data'!$D$24>0,"PASS","FAIL — "&"canonical name not matched in any drawing surface (7/7 surfaces)") -> PASS | P20: =IF(AND(LEN(TRIM(A20&""))>0,TRIM(A20&"")<>"—",LEN(TRIM(B20&""))>0,TRIM(B20&"")<>"—",LEN(TRIM(C20&""))>0,TRIM(C20&"")<>"—",LEN(TRIM(D20&""))>0,TRIM(D20&"")<>"—",LEN(TRIM(K20&""))>0,TRIM(K20&"")<>"—",LEN(TRIM(L20&""))>0,TRIM(L20&"")<>"—",LEN(TRIM(M20&""))>0,TRIM(M20&"")<>"—",LEN(TRIM(N20&""))>0,TRIM(N20&"")<>"—",LEN(TRIM(O20&""))>0,TRIM(O20&"")<>"—"),"PASS","⚠ FAIL — "&"a required cell is empty/placeholder or wrong type") -> PASS
A21: P-107 | B21: Fertigation Dosing Pump | C21: Mass fluid transport process | D21: box | E21: 600 | F21: 510 | G21: 660 | I21: =IF(H21<>"",PI()*(H21/2000)^2*(G21/1000),IF(AND(E21<>"",F21<>"",G21<>""),E21/1000*F21/1000*G21/1000,"")) -> 0.20196 | J21: =IF(H21<>"",PI()*(H21/2000)^2,IF(AND(E21<>"",F21<>""),E21/1000*F21/1000,"")) -> 0.306 | K21: PVC-U / 304 stainless (WRAS) (via fold: P-106) | L21: Grundfos 96122012 · IDENTIFIED (via fold: P-106) | M21: 7/7 (via fold: P-106) | N21: =IF(COUNTIF('Bill of Materials (Ledger)'!$B$5:$B$415,"*"&B21&"*")>0,"PASS","FAIL — "&"canonical name not found in the BoM ledger Item column") -> PASS | O21: =IF('Audit data'!$D$25>0,"PASS","FAIL — "&"canonical name not matched in any drawing surface (7/7 surfaces)") -> PASS | P21: =IF(AND(LEN(TRIM(A21&""))>0,TRIM(A21&"")<>"—",LEN(TRIM(B21&""))>0,TRIM(B21&"")<>"—",LEN(TRIM(C21&""))>0,TRIM(C21&"")<>"—",LEN(TRIM(D21&""))>0,TRIM(D21&"")<>"—",LEN(TRIM(K21&""))>0,TRIM(K21&"")<>"—",LEN(TRIM(L21&""))>0,TRIM(L21&"")<>"—",LEN(TRIM(M21&""))>0,TRIM(M21&"")<>"—",LEN(TRIM(N21&""))>0,TRIM(N21&"")<>"—",LEN(TRIM(O21&""))>0,TRIM(O21&"")<>"—"),"PASS","⚠ FAIL — "&"a required cell is empty/placeholder or wrong type") -> PASS
A22: TK-101 | B22: Cip Tank | C22: Maintenance serviceability | D22: cylinder | G22: 1300 | H22: 1400 | I22: =IF(H22<>"",PI()*(H22/2000)^2*(G22/1000),IF(AND(E22<>"",F22<>"",G22<>""),E22/1000*F22/1000*G22/1000,"")) -> 2.0011945 | J22: =IF(H22<>"",PI()*(H22/2000)^2,IF(AND(E22<>"",F22<>""),E22/1000*F22/1000,"")) -> 1.5393804 | K22: FRP/GRP | L22: made to spec · BESPOKE | M22: 5/7 | N22: =IF(COUNTIF('Bill of Materials (Ledger)'!$B$5:$B$415,"*"&B22&"*")>0,"PASS","FAIL — "&"canonical name not found in the BoM ledger Item column") -> PASS | O22: =IF('Audit data'!$D$26>0,"PASS","FAIL — "&"canonical name not matched in any drawing surface (5/7 surfaces)") -> PASS | P22: =IF(AND(LEN(TRIM(A22&""))>0,TRIM(A22&"")<>"—",LEN(TRIM(B22&""))>0,TRIM(B22&"")<>"—",LEN(TRIM(C22&""))>0,TRIM(C22&"")<>"—",LEN(TRIM(D22&""))>0,TRIM(D22&"")<>"—",LEN(TRIM(K22&""))>0,TRIM(K22&"")<>"—",LEN(TRIM(L22&""))>0,TRIM(L22&"")<>"—",LEN(TRIM(M22&""))>0,TRIM(M22&"")<>"—",LEN(TRIM(N22&""))>0,TRIM(N22&"")<>"—",LEN(TRIM(O22&""))>0,TRIM(O22&"")<>"—"),"PASS","⚠ FAIL — "&"a required cell is empty/placeholder or wrong type") -> PASS
A23: TK-102 | B23: Cleaning Tank | C23: Maintenance serviceability | D23: cylinder | G23: 1300 | H23: 1400 | I23: =IF(H23<>"",PI()*(H23/2000)^2*(G23/1000),IF(AND(E23<>"",F23<>"",G23<>""),E23/1000*F23/1000*G23/1000,"")) -> 2.0011945 | J23: =IF(H23<>"",PI()*(H23/2000)^2,IF(AND(E23<>"",F23<>""),E23/1000*F23/1000,"")) -> 1.5393804 | K23: FRP/GRP | L23: made to spec · BESPOKE | M23: 5/7 | N23: =IF(COUNTIF('Bill of Materials (Ledger)'!$B$5:$B$415,"*"&B23&"*")>0,"PASS","FAIL — "&"canonical name not found in the BoM ledger Item column") -> PASS | O23: =IF('Audit data'!$D$27>0,"PASS","FAIL — "&"canonical name not matched in any drawing surface (5/7 surfaces)") -> PASS | P23: =IF(AND(LEN(TRIM(A23&""))>0,TRIM(A23&"")<>"—",LEN(TRIM(B23&""))>0,TRIM(B23&"")<>"—",LEN(TRIM(C23&""))>0,TRIM(C23&"")<>"—",LEN(TRIM(D23&""))>0,TRIM(D23&"")<>"—",LEN(TRIM(K23&""))>0,TRIM(K23&"")<>"—",LEN(TRIM(L23&""))>0,TRIM(L23&"")<>"—",LEN(TRIM(M23&""))>0,TRIM(M23&"")<>"—",LEN(TRIM(N23&""))>0,TRIM(N23&"")<>"—",LEN(TRIM(O23&""))>0,TRIM(O23&"")<>"—"),"PASS","⚠ FAIL — "&"a required cell is empty/placeholder or wrong type") -> PASS
A24: TK-103 | B24: Nutrient Tank | C24: Mass fluid transport process | D24: cylinder | G24: 1100 | H24: 1100 | I24: =IF(H24<>"",PI()*(H24/2000)^2*(G24/1000),IF(AND(E24<>"",F24<>"",G24<>""),E24/1000*F24/1000*G24/1000,"")) -> 1.045365 | J24: =IF(H24<>"",PI()*(H24/2000)^2,IF(AND(E24<>"",F24<>""),E24/1000*F24/1000,"")) -> 0.95033178 | K24: FRP/GRP | L24: made to spec · BESPOKE | M24: 5/7 | N24: =IF(COUNTIF('Bill of Materials (Ledger)'!$B$5:$B$415,"*"&B24&"*")>0,"PASS","FAIL — "&"canonical name not found in the BoM ledger Item column") -> PASS | O24: =IF('Audit data'!$D$28>0,"PASS","FAIL — "&"canonical name not matched in any drawing surface (5/7 surfaces)") -> PASS | P24: =IF(AND(LEN(TRIM(A24&""))>0,TRIM(A24&"")<>"—",LEN(TRIM(B24&""))>0,TRIM(B24&"")<>"—",LEN(TRIM(C24&""))>0,TRIM(C24&"")<>"—",LEN(TRIM(D24&""))>0,TRIM(D24&"")<>"—",LEN(TRIM(K24&""))>0,TRIM(K24&"")<>"—",LEN(TRIM(L24&""))>0,TRIM(L24&"")<>"—",LEN(TRIM(M24&""))>0,TRIM(M24&"")<>"—",LEN(TRIM(N24&""))>0,TRIM(N24&"")<>"—",LEN(TRIM(O24&""))>0,TRIM(O24&"")<>"—"),"PASS","⚠ FAIL — "&"a required cell is empty/placeholder or wrong type") -> PASS
A25: TK-104 | B25: Nutrient Tank | C25: Mass fluid transport process | D25: cylinder | G25: 1100 | H25: 1100 | I25: =IF(H25<>"",PI()*(H25/2000)^2*(G25/1000),IF(AND(E25<>"",F25<>"",G25<>""),E25/1000*F25/1000*G25/1000,"")) -> 1.045365 | J25: =IF(H25<>"",PI()*(H25/2000)^2,IF(AND(E25<>"",F25<>""),E25/1000*F25/1000,"")) -> 0.95033178 | K25: FRP/GRP (via fold: TK-103) | L25: made to spec · BESPOKE (via fold: TK-103) | M25: 5/7 (via fold: TK-103) | N25: =IF(COUNTIF('Bill of Materials (Ledger)'!$B$5:$B$415,"*"&B25&"*")>0,"PASS","FAIL — "&"canonical name not found in the BoM ledger Item column") -> PASS | O25: =IF('Audit data'!$D$29>0,"PASS","FAIL — "&"canonical name not matched in any drawing surface (5/7 surfaces)") -> PASS | P25: =IF(AND(LEN(TRIM(A25&""))>0,TRIM(A25&"")<>"—",LEN(TRIM(B25&""))>0,TRIM(B25&"")<>"—",LEN(TRIM(C25&""))>0,TRIM(C25&"")<>"—",LEN(TRIM(D25&""))>0,TRIM(D25&"")<>"—",LEN(TRIM(K25&""))>0,TRIM(K25&"")<>"—",LEN(TRIM(L25&""))>0,TRIM(L25&"")<>"—",LEN(TRIM(M25&""))>0,TRIM(M25&"")<>"—",LEN(TRIM(N25&""))>0,TRIM(N25&"")<>"—",LEN(TRIM(O25&""))>0,TRIM(O25&"")<>"—"),"PASS","⚠ FAIL — "&"a required cell is empty/placeholder or wrong type") -> PASS
A26: TK-105 | B26: Nutrient Tank | C26: Mass fluid transport process | D26: cylinder | G26: 1100 | H26: 1100 | I26: =IF(H26<>"",PI()*(H26/2000)^2*(G26/1000),IF(AND(E26<>"",F26<>"",G26<>""),E26/1000*F26/1000*G26/1000,"")) -> 1.045365 | J26: =IF(H26<>"",PI()*(H26/2000)^2,IF(AND(E26<>"",F26<>""),E26/1000*F26/1000,"")) -> 0.95033178 | K26: FRP/GRP (via fold: TK-103) | L26: made to spec · BESPOKE (via fold: TK-103) | M26: 5/7 (via fold: TK-103) | N26: =IF(COUNTIF('Bill of Materials (Ledger)'!$B$5:$B$415,"*"&B26&"*")>0,"PASS","FAIL — "&"canonical name not found in the BoM ledger Item column") -> PASS | O26: =IF('Audit data'!$D$30>0,"PASS","FAIL — "&"canonical name not matched in any drawing surface (5/7 surfaces)") -> PASS | P26: =IF(AND(LEN(TRIM(A26&""))>0,TRIM(A26&"")<>"—",LEN(TRIM(B26&""))>0,TRIM(B26&"")<>"—",LEN(TRIM(C26&""))>0,TRIM(C26&"")<>"—",LEN(TRIM(D26&""))>0,TRIM(D26&"")<>"—",LEN(TRIM(K26&""))>0,TRIM(K26&"")<>"—",LEN(TRIM(L26&""))>0,TRIM(L26&"")<>"—",LEN(TRIM(M26&""))>0,TRIM(M26&"")<>"—",LEN(TRIM(N26&""))>0,TRIM(N26&"")<>"—",LEN(TRIM(O26&""))>0,TRIM(O26&"")<>"—"),"PASS","⚠ FAIL — "&"a required cell is empty/placeholder or wrong type") -> PASS
A27: TK-106 | B27: Drain Water Tank | C27: Mass fluid transport process | D27: cylinder | G27: 3700 | H27: 3700 | I27: =IF(H27<>"",PI()*(H27/2000)^2*(G27/1000),IF(AND(E27<>"",F27<>"",G27<>""),E27/1000*F27/1000*G27/1000,"")) -> 39.782773 | J27: =IF(H27<>"",PI()*(H27/2000)^2,IF(AND(E27<>"",F27<>""),E27/1000*F27/1000,"")) -> 10.752101 | K27: FRP/GRP | L27: made to spec · BESPOKE | M27: 5/7 | N27: =IF(COUNTIF('Bill of Materials (Ledger)'!$B$5:$B$415,"*"&B27&"*")>0,"PASS","FAIL — "&"canonical name not found in the BoM ledger Item column") -> PASS | O27: =IF('Audit data'!$D$31>0,"PASS","FAIL — "&"canonical name not matched in any drawing surface (5/7 surfaces)") -> PASS | P27: =IF(AND(LEN(TRIM(A27&""))>0,TRIM(A27&"")<>"—",LEN(TRIM(B27&""))>0,TRIM(B27&"")<>"—",LEN(TRIM(C27&""))>0,TRIM(C27&"")<>"—",LEN(TRIM(D27&""))>0,TRIM(D27&"")<>"—",LEN(TRIM(K27&""))>0,TRIM(K27&"")<>"—",LEN(TRIM(L27&""))>0,TRIM(L27&"")<>"—",LEN(TRIM(M27&""))>0,TRIM(M27&"")<>"—",LEN(TRIM(N27&""))>0,TRIM(N27&"")<>"—",LEN(TRIM(O27&""))>0,TRIM(O27&"")<>"—"),"PASS","⚠ FAIL — "&"a required cell is empty/placeholder or wrong type") -> PASS
A28: TK-107 | B28: Drain Water Tank | C28: Mass fluid transport process | D28: cylinder | G28: 3700 | H28: 3700 | I28: =IF(H28<>"",PI()*(H28/2000)^2*(G28/1000),IF(AND(E28<>"",F28<>"",G28<>""),E28/1000*F28/1000*G28/1000,"")) -> 39.782773 | J28: =IF(H28<>"",PI()*(H28/2000)^2,IF(AND(E28<>"",F28<>""),E28/1000*F28/1000,"")) -> 10.752101 | K28: FRP/GRP (via fold: TK-106) | L28: made to spec · BESPOKE (via fold: TK-106) | M28: 5/7 (via fold: TK-106) | N28: =IF(COUNTIF('Bill of Materials (Ledger)'!$B$5:$B$415,"*"&B28&"*")>0,"PASS","FAIL — "&"canonical name not found in the BoM ledger Item column") -> PASS | O28: =IF('Audit data'!$D$32>0,"PASS","FAIL — "&"canonical name not matched in any drawing surface (5/7 surfaces)") -> PASS | P28: =IF(AND(LEN(TRIM(A28&""))>0,TRIM(A28&"")<>"—",LEN(TRIM(B28&""))>0,TRIM(B28&"")<>"—",LEN(TRIM(C28&""))>0,TRIM(C28&"")<>"—",LEN(TRIM(D28&""))>0,TRIM(D28&"")<>"—",LEN(TRIM(K28&""))>0,TRIM(K28&"")<>"—",LEN(TRIM(L28&""))>0,TRIM(L28&"")<>"—",LEN(TRIM(M28&""))>0,TRIM(M28&"")<>"—",LEN(TRIM(N28&""))>0,TRIM(N28&"")<>"—",LEN(TRIM(O28&""))>0,TRIM(O28&"")<>"—"),"PASS","⚠ FAIL — "&"a required cell is empty/placeholder or wrong type") -> PASS
A29: TK-108 | B29: Fresh Water Tank | C29: Mass fluid transport process | D29: cylinder | G29: 3700 | H29: 3700 | I29: =IF(H29<>"",PI()*(H29/2000)^2*(G29/1000),IF(AND(E29<>"",F29<>"",G29<>""),E29/1000*F29/1000*G29/1000,"")) -> 39.782773 | J29: =IF(H29<>"",PI()*(H29/2000)^2,IF(AND(E29<>"",F29<>""),E29/1000*F29/1000,"")) -> 10.752101 | K29: FRP/GRP | L29: made to spec · BESPOKE | M29: 5/7 | N29: =IF(COUNTIF('Bill of Materials (Ledger)'!$B$5:$B$415,"*"&B29&"*")>0,"PASS","FAIL — "&"canonical name not found in the BoM ledger Item column") -> PASS | O29: =IF('Audit data'!$D$33>0,"PASS","FAIL — "&"canonical name not matched in any drawing surface (5/7 surfaces)") -> PASS | P29: =IF(AND(LEN(TRIM(A29&""))>0,TRIM(A29&"")<>"—",LEN(TRIM(B29&""))>0,TRIM(B29&"")<>"—",LEN(TRIM(C29&""))>0,TRIM(C29&"")<>"—",LEN(TRIM(D29&""))>0,TRIM(D29&"")<>"—",LEN(TRIM(K29&""))>0,TRIM(K29&"")<>"—",LEN(TRIM(L29&""))>0,TRIM(L29&"")<>"—",LEN(TRIM(M29&""))>0,TRIM(M29&"")<>"—",LEN(TRIM(N29&""))>0,TRIM(N29&"")<>"—",LEN(TRIM(O29&""))>0,TRIM(O29&"")<>"—"),"PASS","⚠ FAIL — "&"a required cell is empty/placeholder or wrong type") -> PASS
A30: TK-109 | B30: Nutrient Tank | C30: Mass fluid transport process | D30: cylinder | G30: 1100 | H30: 1100 | I30: =IF(H30<>"",PI()*(H30/2000)^2*(G30/1000),IF(AND(E30<>"",F30<>"",G30<>""),E30/1000*F30/1000*G30/1000,"")) -> 1.045365 | J30: =IF(H30<>"",PI()*(H30/2000)^2,IF(AND(E30<>"",F30<>""),E30/1000*F30/1000,"")) -> 0.95033178 | K30: FRP/GRP (via fold: TK-103) | L30: made to spec · BESPOKE (via fold: TK-103) | M30: 5/7 (via fold: TK-103) | N30: =IF(COUNTIF('Bill of Materials (Ledger)'!$B$5:$B$415,"*"&B30&"*")>0,"PASS","FAIL — "&"canonical name not found in the BoM ledger Item column") -> PASS | O30: =IF('Audit data'!$D$34>0,"PASS","FAIL — "&"canonical name not matched in any drawing surface (5/7 surfaces)") -> PASS | P30: =IF(AND(LEN(TRIM(A30&""))>0,TRIM(A30&"")<>"—",LEN(TRIM(B30&""))>0,TRIM(B30&"")<>"—",LEN(TRIM(C30&""))>0,TRIM(C30&"")<>"—",LEN(TRIM(D30&""))>0,TRIM(D30&"")<>"—",LEN(TRIM(K30&""))>0,TRIM(K30&"")<>"—",LEN(TRIM(L30&""))>0,TRIM(L30&"")<>"—",LEN(TRIM(M30&""))>0,TRIM(M30&"")<>"—",LEN(TRIM(N30&""))>0,TRIM(N30&"")<>"—",LEN(TRIM(O30&""))>0,TRIM(O30&"")<>"—"),"PASS","⚠ FAIL — "&"a required cell is empty/placeholder or wrong type") -> PASS
A31: TK-110 | B31: Nutrient Tank | C31: Mass fluid transport process | D31: cylinder | G31: 1100 | H31: 1100 | I31: =IF(H31<>"",PI()*(H31/2000)^2*(G31/1000),IF(AND(E31<>"",F31<>"",G31<>""),E31/1000*F31/1000*G31/1000,"")) -> 1.045365 | J31: =IF(H31<>"",PI()*(H31/2000)^2,IF(AND(E31<>"",F31<>""),E31/1000*F31/1000,"")) -> 0.95033178 | K31: FRP/GRP (via fold: TK-103) | L31: made to spec · BESPOKE (via fold: TK-103) | M31: 5/7 (via fold: TK-103) | N31: =IF(COUNTIF('Bill of Materials (Ledger)'!$B$5:$B$415,"*"&B31&"*")>0,"PASS","FAIL — "&"canonical name not found in the BoM ledger Item column") -> PASS | O31: =IF('Audit data'!$D$35>0,"PASS","FAIL — "&"canonical name not matched in any drawing surface (5/7 surfaces)") -> PASS | P31: =IF(AND(LEN(TRIM(A31&""))>0,TRIM(A31&"")<>"—",LEN(TRIM(B31&""))>0,TRIM(B31&"")<>"—",LEN(TRIM(C31&""))>0,TRIM(C31&"")<>"—",LEN(TRIM(D31&""))>0,TRIM(D31&"")<>"—",LEN(TRIM(K31&""))>0,TRIM(K31&"")<>"—",LEN(TRIM(L31&""))>0,TRIM(L31&"")<>"—",LEN(TRIM(M31&""))>0,TRIM(M31&"")<>"—",LEN(TRIM(N31&""))>0,TRIM(N31&"")<>"—",LEN(TRIM(O31&""))>0,TRIM(O31&"")<>"—"),"PASS","⚠ FAIL — "&"a required cell is empty/placeholder or wrong type") -> PASS
A32: TK-111 | B32: Nutrient Tank | C32: Mass fluid transport process | D32: cylinder | G32: 1100 | H32: 1100 | I32: =IF(H32<>"",PI()*(H32/2000)^2*(G32/1000),IF(AND(E32<>"",F32<>"",G32<>""),E32/1000*F32/1000*G32/1000,"")) -> 1.045365 | J32: =IF(H32<>"",PI()*(H32/2000)^2,IF(AND(E32<>"",F32<>""),E32/1000*F32/1000,"")) -> 0.95033178 | K32: FRP/GRP (via fold: TK-103) | L32: made to spec · BESPOKE (via fold: TK-103) | M32: 5/7 (via fold: TK-103) | N32: =IF(COUNTIF('Bill of Materials (Ledger)'!$B$5:$B$415,"*"&B32&"*")>0,"PASS","FAIL — "&"canonical name not found in the BoM ledger Item column") -> PASS | O32: =IF('Audit data'!$D$36>0,"PASS","FAIL — "&"canonical name not matched in any drawing surface (5/7 surfaces)") -> PASS | P32: =IF(AND(LEN(TRIM(A32&""))>0,TRIM(A32&"")<>"—",LEN(TRIM(B32&""))>0,TRIM(B32&"")<>"—",LEN(TRIM(C32&""))>0,TRIM(C32&"")<>"—",LEN(TRIM(D32&""))>0,TRIM(D32&"")<>"—",LEN(TRIM(K32&""))>0,TRIM(K32&"")<>"—",LEN(TRIM(L32&""))>0,TRIM(L32&"")<>"—",LEN(TRIM(M32&""))>0,TRIM(M32&"")<>"—",LEN(TRIM(N32&""))>0,TRIM(N32&"")<>"—",LEN(TRIM(O32&""))>0,TRIM(O32&"")<>"—"),"PASS","⚠ FAIL — "&"a required cell is empty/placeholder or wrong type") -> PASS
A33: TK-112 | B33: Nutrient Tank | C33: Mass fluid transport process | D33: cylinder | G33: 1100 | H33: 1100 | I33: =IF(H33<>"",PI()*(H33/2000)^2*(G33/1000),IF(AND(E33<>"",F33<>"",G33<>""),E33/1000*F33/1000*G33/1000,"")) -> 1.045365 | J33: =IF(H33<>"",PI()*(H33/2000)^2,IF(AND(E33<>"",F33<>""),E33/1000*F33/1000,"")) -> 0.95033178 | K33: FRP/GRP (via fold: TK-103) | L33: made to spec · BESPOKE (via fold: TK-103) | M33: 5/7 (via fold: TK-103) | N33: =IF(COUNTIF('Bill of Materials (Ledger)'!$B$5:$B$415,"*"&B33&"*")>0,"PASS","FAIL — "&"canonical name not found in the BoM ledger Item column") -> PASS | O33: =IF('Audit data'!$D$37>0,"PASS","FAIL — "&"canonical name not matched in any drawing surface (5/7 surfaces)") -> PASS | P33: =IF(AND(LEN(TRIM(A33&""))>0,TRIM(A33&"")<>"—",LEN(TRIM(B33&""))>0,TRIM(B33&"")<>"—",LEN(TRIM(C33&""))>0,TRIM(C33&"")<>"—",LEN(TRIM(D33&""))>0,TRIM(D33&"")<>"—",LEN(TRIM(K33&""))>0,TRIM(K33&"")<>"—",LEN(TRIM(L33&""))>0,TRIM(L33&"")<>"—",LEN(TRIM(M33&""))>0,TRIM(M33&"")<>"—",LEN(TRIM(N33&""))>0,TRIM(N33&"")<>"—",LEN(TRIM(O33&""))>0,TRIM(O33&"")<>"—"),"PASS","⚠ FAIL — "&"a required cell is empty/placeholder or wrong type") -> PASS
